Workbook

Sheet Results
A1: Showing sheet: | B1: Witches Triple Crown | D1: Par: | E1: =IFERROR(INDIRECT("'"&$B$1&"'!P5"),"") -> 0.012409875
A2: Team | B2: Runner | C2: Rank | D2: Fastest Time | E2: Target | F2: Score | H2: Team | I2: Team Score | J2: Rank
A3: =IF($B3="","",INDIRECT("'"&$B$1&"'!A"&ROW()-1)) -> 1 | B3: =IF(INDIRECT("'"&$B$1&"'!B"&ROW()-1)=0,"",INDIRECT("'"&$B$1&"'!B"&ROW()-1)) -> Ben Wernick | C3: =IF(OR($B3="",$D3=""),"",RANK($D3,$D$3:$D$37,1)) -> 12 | D3: =IF($B3="","",IF(INDIRECT("'"&$B$1&"'!C"&ROW()-1)=0,"",INDIRECT("'"&$B$1&"'!C"&ROW()-1))) -> 0.023958333 | E3: =IF($B3="","",INDIRECT("'"&$B$1&"'!G"&ROW()-1)) -> 0.012473256 | F3: =IF($B3="","",INDIRECT("'"&$B$1&"'!H"&ROW()-1)) -> -0.05 | H3: 1 | I3: =IF(COUNTIF($A$3:$A$37,$H3)=0,"",AVERAGEIF($A$3:$A$37,$H3,$F$3:$F$37)) -> -0.0625 | J3: =IF($I3="","",RANK($I3,$I$3:$I$9)) -> 6
A4: =IF($B4="","",INDIRECT("'"&$B$1&"'!A"&ROW()-1)) -> 1 | B4: =IF(INDIRECT("'"&$B$1&"'!B"&ROW()-1)=0,"",INDIRECT("'"&$B$1&"'!B"&ROW()-1)) -> Tom Rhoden | C4: =IF(OR($B4="",$D4=""),"",RANK($D4,$D$3:$D$37,1)) -> 13 | D4: =IF($B4="","",IF(INDIRECT("'"&$B$1&"'!C"&ROW()-1)=0,"",INDIRECT("'"&$B$1&"'!C"&ROW()-1))) -> 0.023993056 | E4: =IF($B4="","",INDIRECT("'"&$B$1&"'!G"&ROW()-1)) -> 0.013452462 | F4: =IF($B4="","",INDIRECT("'"&$B$1&"'!H"&ROW()-1)) -> -0.05 | H4: 2 | I4: =IF(COUNTIF($A$3:$A$37,$H4)=0,"",AVERAGEIF($A$3:$A$37,$H4,$F$3:$F$37)) -> -0.027408683 | J4: =IF($I4="","",RANK($I4,$I$3:$I$9)) -> 1
A5: =IF($B5="","",INDIRECT("'"&$B$1&"'!A"&ROW()-1)) -> 1 | B5: =IF(INDIRECT("'"&$B$1&"'!B"&ROW()-1)=0,"",INDIRECT("'"&$B$1&"'!B"&ROW()-1)) -> Anne Marie Moon | C5: =IF(OR($B5="",$D5=""),"",RANK($D5,$D$3:$D$37,1)) | D5: =IF($B5="","",IF(INDIRECT("'"&$B$1&"'!C"&ROW()-1)=0,"",INDIRECT("'"&$B$1&"'!C"&ROW()-1))) | E5: =IF($B5="","",INDIRECT("'"&$B$1&"'!G"&ROW()-1)) -> 0.014497942 | F5: =IF($B5="","",INDIRECT("'"&$B$1&"'!H"&ROW()-1)) -> -0.075 | H5: 3 | I5: =IF(COUNTIF($A$3:$A$37,$H5)=0,"",AVERAGEIF($A$3:$A$37,$H5,$F$3:$F$37)) -> -0.047033524 | J5: =IF($I5="","",RANK($I5,$I$3:$I$9)) -> 3
A6: =IF($B6="","",INDIRECT("'"&$B$1&"'!A"&ROW()-1)) -> 1 | B6: =IF(INDIRECT("'"&$B$1&"'!B"&ROW()-1)=0,"",INDIRECT("'"&$B$1&"'!B"&ROW()-1)) -> Lisa King | C6: =IF(OR($B6="",$D6=""),"",RANK($D6,$D$3:$D$37,1)) | D6: =IF($B6="","",IF(INDIRECT("'"&$B$1&"'!C"&ROW()-1)=0,"",INDIRECT("'"&$B$1&"'!C"&ROW()-1))) | E6: =IF($B6="","",INDIRECT("'"&$B$1&"'!G"&ROW()-1)) -> 0.015601519 | F6: =IF($B6="","",INDIRECT("'"&$B$1&"'!H"&ROW()-1)) -> -0.075 | H6: 4 | I6: =IF(COUNTIF($A$3:$A$37,$H6)=0,"",AVERAGEIF($A$3:$A$37,$H6,$F$3:$F$37)) -> -0.05625 | J6: =IF($I6="","",RANK($I6,$I$3:$I$9)) -> 4
A7: =IF($B7="","",INDIRECT("'"&$B$1&"'!A"&ROW()-1)) -> 2 | B7: =IF(INDIRECT("'"&$B$1&"'!B"&ROW()-1)=0,"",INDIRECT("'"&$B$1&"'!B"&ROW()-1)) -> Luke Sibieta | C7: =IF(OR($B7="",$D7=""),"",RANK($D7,$D$3:$D$37,1)) -> 2 | D7: =IF($B7="","",IF(INDIRECT("'"&$B$1&"'!C"&ROW()-1)=0,"",INDIRECT("'"&$B$1&"'!C"&ROW()-1))) -> 0.013263889 | E7: =IF($B7="","",INDIRECT("'"&$B$1&"'!G"&ROW()-1)) -> 0.013137314 | F7: =IF($B7="","",INDIRECT("'"&$B$1&"'!H"&ROW()-1)) -> -0.0096347303 | H7: 5 | I7: =IF(COUNTIF($A$3:$A$37,$H7)=0,"",AVERAGEIF($A$3:$A$37,$H7,$F$3:$F$37)) -> -0.075 | J7: =IF($I7="","",RANK($I7,$I$3:$I$9)) -> 7
A8: =IF($B8="","",INDIRECT("'"&$B$1&"'!A"&ROW()-1)) -> 2 | B8: =IF(INDIRECT("'"&$B$1&"'!B"&ROW()-1)=0,"",INDIRECT("'"&$B$1&"'!B"&ROW()-1)) -> Mark Emery | C8: =IF(OR($B8="",$D8=""),"",RANK($D8,$D$3:$D$37,1)) -> 1 | D8: =IF($B8="","",IF(INDIRECT("'"&$B$1&"'!C"&ROW()-1)=0,"",INDIRECT("'"&$B$1&"'!C"&ROW()-1))) -> 0.01275463 | E8: =IF($B8="","",INDIRECT("'"&$B$1&"'!G"&ROW()-1)) -> 0.012077048 | F8: =IF($B8="","",INDIRECT("'"&$B$1&"'!H"&ROW()-1)) -> -0.05 | H8: 6 | I8: =IF(COUNTIF($A$3:$A$37,$H8)=0,"",AVERAGEIF($A$3:$A$37,$H8,$F$3:$F$37)) -> -0.06 | J8: =IF($I8="","",RANK($I8,$I$3:$I$9)) -> 5
A9: =IF($B9="","",INDIRECT("'"&$B$1&"'!A"&ROW()-1)) -> 2 | B9: =IF(INDIRECT("'"&$B$1&"'!B"&ROW()-1)=0,"",INDIRECT("'"&$B$1&"'!B"&ROW()-1)) -> Matt Snell | C9: =IF(OR($B9="",$D9=""),"",RANK($D9,$D$3:$D$37,1)) -> 4 | D9: =IF($B9="","",IF(INDIRECT("'"&$B$1&"'!C"&ROW()-1)=0,"",INDIRECT("'"&$B$1&"'!C"&ROW()-1))) -> 0.013912037 | E9: =IF($B9="","",INDIRECT("'"&$B$1&"'!G"&ROW()-1)) -> 0.013912037 | F9: =IF($B9="","",INDIRECT("'"&$B$1&"'!H"&ROW()-1)) -> 0 | H9: 7 | I9: =IF(COUNTIF($A$3:$A$37,$H9)=0,"",AVERAGEIF($A$3:$A$37,$H9,$F$3:$F$37)) -> -0.04539704 | J9: =IF($I9="","",RANK($I9,$I$3:$I$9)) -> 2
A10: =IF($B10="","",INDIRECT("'"&$B$1&"'!A"&ROW()-1)) -> 2 | B10: =IF(INDIRECT("'"&$B$1&"'!B"&ROW()-1)=0,"",INDIRECT("'"&$B$1&"'!B"&ROW()-1)) -> Gareth Lawrence | C10: =IF(OR($B10="",$D10=""),"",RANK($D10,$D$3:$D$37,1)) -> 15 | D10: =IF($B10="","",IF(INDIRECT("'"&$B$1&"'!C"&ROW()-1)=0,"",INDIRECT("'"&$B$1&"'!C"&ROW()-1))) -> 0.026122685 | E10: =IF($B10="","",INDIRECT("'"&$B$1&"'!G"&ROW()-1)) -> 0.015979116 | F10: =IF($B10="","",INDIRECT("'"&$B$1&"'!H"&ROW()-1)) -> -0.05
A11: =IF($B11="","",INDIRECT("'"&$B$1&"'!A"&ROW()-1)) -> 3 | B11: =IF(INDIRECT("'"&$B$1&"'!B"&ROW()-1)=0,"",INDIRECT("'"&$B$1&"'!B"&ROW()-1)) -> Neil Price | C11: =IF(OR($B11="",$D11=""),"",RANK($D11,$D$3:$D$37,1)) -> 5 | D11: =IF($B11="","",IF(INDIRECT("'"&$B$1&"'!C"&ROW()-1)=0,"",INDIRECT("'"&$B$1&"'!C"&ROW()-1))) -> 0.014907407 | E11: =IF($B11="","",INDIRECT("'"&$B$1&"'!G"&ROW()-1)) -> 0.015041266 | F11: =IF($B11="","",INDIRECT("'"&$B$1&"'!H"&ROW()-1)) -> 0.0088994282
A12: =IF($B12="","",INDIRECT("'"&$B$1&"'!A"&ROW()-1)) -> 3 | B12: =IF(INDIRECT("'"&$B$1&"'!B"&ROW()-1)=0,"",INDIRECT("'"&$B$1&"'!B"&ROW()-1)) -> Rhidian Jones | C12: =IF(OR($B12="",$D12=""),"",RANK($D12,$D$3:$D$37,1)) | D12: =IF($B12="","",IF(INDIRECT("'"&$B$1&"'!C"&ROW()-1)=0,"",INDIRECT("'"&$B$1&"'!C"&ROW()-1))) | E12: =IF($B12="","",INDIRECT("'"&$B$1&"'!G"&ROW()-1)) -> 0.015331216 | F12: =IF($B12="","",INDIRECT("'"&$B$1&"'!H"&ROW()-1)) -> -0.075
A13: =IF($B13="","",INDIRECT("'"&$B$1&"'!A"&ROW()-1)) -> 3 | B13: =IF(INDIRECT("'"&$B$1&"'!B"&ROW()-1)=0,"",INDIRECT("'"&$B$1&"'!B"&ROW()-1)) -> Andy Shanahan | C13: =IF(OR($B13="",$D13=""),"",RANK($D13,$D$3:$D$37,1)) | D13: =IF($B13="","",IF(INDIRECT("'"&$B$1&"'!C"&ROW()-1)=0,"",INDIRECT("'"&$B$1&"'!C"&ROW()-1))) | E13: =IF($B13="","",INDIRECT("'"&$B$1&"'!G"&ROW()-1)) -> 0.016664953 | F13: =IF($B13="","",INDIRECT("'"&$B$1&"'!H"&ROW()-1)) -> -0.075
A14: =IF($B14="","",INDIRECT("'"&$B$1&"'!A"&ROW()-1)) -> 4 | B14: =IF(INDIRECT("'"&$B$1&"'!B"&ROW()-1)=0,"",INDIRECT("'"&$B$1&"'!B"&ROW()-1)) -> Rachel Price | C14: =IF(OR($B14="",$D14=""),"",RANK($D14,$D$3:$D$37,1)) -> 14 | D14: =IF($B14="","",IF(INDIRECT("'"&$B$1&"'!C"&ROW()-1)=0,"",INDIRECT("'"&$B$1&"'!C"&ROW()-1))) -> 0.025706019 | E14: =IF($B14="","",INDIRECT("'"&$B$1&"'!G"&ROW()-1)) -> 0.01589356 | F14: =IF($B14="","",INDIRECT("'"&$B$1&"'!H"&ROW()-1)) -> -0.05
A15: =IF($B15="","",INDIRECT("'"&$B$1&"'!A"&ROW()-1)) -> 4 | B15: =IF(INDIRECT("'"&$B$1&"'!B"&ROW()-1)=0,"",INDIRECT("'"&$B$1&"'!B"&ROW()-1)) -> Emma Jones | C15: =IF(OR($B15="",$D15=""),"",RANK($D15,$D$3:$D$37,1)) -> 7 | D15: =IF($B15="","",IF(INDIRECT("'"&$B$1&"'!C"&ROW()-1)=0,"",INDIRECT("'"&$B$1&"'!C"&ROW()-1))) -> 0.021597222 | E15: =IF($B15="","",INDIRECT("'"&$B$1&"'!G"&ROW()-1)) -> 0.019572086 | F15: =IF($B15="","",INDIRECT("'"&$B$1&"'!H"&ROW()-1)) -> -0.05
A16: =IF($B16="","",INDIRECT("'"&$B$1&"'!A"&ROW()-1)) -> 4 | B16: =IF(INDIRECT("'"&$B$1&"'!B"&ROW()-1)=0,"",INDIRECT("'"&$B$1&"'!B"&ROW()-1)) -> Claire Emery | C16: =IF(OR($B16="",$D16=""),"",RANK($D16,$D$3:$D$37,1)) | D16: =IF($B16="","",IF(INDIRECT("'"&$B$1&"'!C"&ROW()-1)=0,"",INDIRECT("'"&$B$1&"'!C"&ROW()-1))) | E16: =IF($B16="","",INDIRECT("'"&$B$1&"'!G"&ROW()-1)) -> 0.019781067 | F16: =IF($B16="","",INDIRECT("'"&$B$1&"'!H"&ROW()-1)) -> -0.075
A17: =IF($B17="","",INDIRECT("'"&$B$1&"'!A"&ROW()-1)) -> 4 | B17: =IF(INDIRECT("'"&$B$1&"'!B"&ROW()-1)=0,"",INDIRECT("'"&$B$1&"'!B"&ROW()-1)) -> Helen Lawrence | C17: =IF(OR($B17="",$D17=""),"",RANK($D17,$D$3:$D$37,1)) -> 8 | D17: =IF($B17="","",IF(INDIRECT("'"&$B$1&"'!C"&ROW()-1)=0,"",INDIRECT("'"&$B$1&"'!C"&ROW()-1))) -> 0.021770833 | E17: =IF($B17="","",INDIRECT("'"&$B$1&"'!G"&ROW()-1)) -> 0.019918196 | F17: =IF($B17="","",INDIRECT("'"&$B$1&"'!H"&ROW()-1)) -> -0.05
A18: =IF($B18="","",INDIRECT("'"&$B$1&"'!A"&ROW()-1)) -> 5 | B18: =IF(INDIRECT("'"&$B$1&"'!B"&ROW()-1)=0,"",INDIRECT("'"&$B$1&"'!B"&ROW()-1)) -> Ebony Vanderras | C18: =IF(OR($B18="",$D18=""),"",RANK($D18,$D$3:$D$37,1)) | D18: =IF($B18="","",IF(INDIRECT("'"&$B$1&"'!C"&ROW()-1)=0,"",INDIRECT("'"&$B$1&"'!C"&ROW()-1))) | E18: =IF($B18="","",INDIRECT("'"&$B$1&"'!G"&ROW()-1)) -> 0.013627025 | F18: =IF($B18="","",INDIRECT("'"&$B$1&"'!H"&ROW()-1)) -> -0.075
A19: =IF($B19="","",INDIRECT("'"&$B$1&"'!A"&ROW()-1)) -> 5 | B19: =IF(INDIRECT("'"&$B$1&"'!B"&ROW()-1)=0,"",INDIRECT("'"&$B$1&"'!B"&ROW()-1)) -> Jennifer Morris | C19: =IF(OR($B19="",$D19=""),"",RANK($D19,$D$3:$D$37,1)) | D19: =IF($B19="","",IF(INDIRECT("'"&$B$1&"'!C"&ROW()-1)=0,"",INDIRECT("'"&$B$1&"'!C"&ROW()-1))) | E19: =IF($B19="","",INDIRECT("'"&$B$1&"'!G"&ROW()-1)) -> 0.017532773 | F19: =IF($B19="","",INDIRECT("'"&$B$1&"'!H"&ROW()-1)) -> -0.075
A20: =IF($B20="","",INDIRECT("'"&$B$1&"'!A"&ROW()-1)) -> 5 | B20: =IF(INDIRECT("'"&$B$1&"'!B"&ROW()-1)=0,"",INDIRECT("'"&$B$1&"'!B"&ROW()-1)) -> Keziah Rhoden | C20: =IF(OR($B20="",$D20=""),"",RANK($D20,$D$3:$D$37,1)) | D20: =IF($B20="","",IF(INDIRECT("'"&$B$1&"'!C"&ROW()-1)=0,"",INDIRECT("'"&$B$1&"'!C"&ROW()-1))) | E20: =IF($B20="","",INDIRECT("'"&$B$1&"'!G"&ROW()-1)) -> 0.018371451 | F20: =IF($B20="","",INDIRECT("'"&$B$1&"'!H"&ROW()-1)) -> -0.075
A21: =IF($B21="","",INDIRECT("'"&$B$1&"'!A"&ROW()-1)) -> 5 | B21: =IF(INDIRECT("'"&$B$1&"'!B"&ROW()-1)=0,"",INDIRECT("'"&$B$1&"'!B"&ROW()-1)) -> Lizz Ryan | C21: =IF(OR($B21="",$D21=""),"",RANK($D21,$D$3:$D$37,1)) | D21: =IF($B21="","",IF(INDIRECT("'"&$B$1&"'!C"&ROW()-1)=0,"",INDIRECT("'"&$B$1&"'!C"&ROW()-1))) | E21: =IF($B21="","",INDIRECT("'"&$B$1&"'!G"&ROW()-1)) -> 0.021014134 | F21: =IF($B21="","",INDIRECT("'"&$B$1&"'!H"&ROW()-1)) -> -0.075
... A37: =IF($B37="","",INDIRECT("'"&$B$1&"'!A"&ROW()-1)) | B37: =IF(INDIRECT("'"&$B$1&"'!B"&ROW()-1)=0,"",INDIRECT("'"&$B$1&"'!B"&ROW()-1)) | C37: =IF(OR($B37="",$D37=""),"",RANK($D37,$D$3:$D$37,1)) | D37: =IF($B37="","",IF(INDIRECT("'"&$B$1&"'!C"&ROW()-1)=0,"",INDIRECT("'"&$B$1&"'!C"&ROW()-1))) | E37: =IF($B37="","",INDIRECT("'"&$B$1&"'!G"&ROW()-1)) | F37: =IF($B37="","",INDIRECT("'"&$B$1&"'!H"&ROW()-1))

Sheet Control
A1: Setting | B1: Value
A2: Panel runner 1 | B2: Ben Wernick
A3: Panel runner 2 | B3: Mark Emery
A4: Panel runner 3 | B4: Anne Marie Moon
A5: Standard weight | B5: =1/3 -> 0.33333333
A6: Calibration weight (new/returning) | B6: 0.75
A7: Score cap (upper) | B7: 0.05
A8: Score cap (lower) | B8: -0.05
A9: No-run penalty | B9: -0.075
A10: Calibration runs granted | B10: 3
A11: Miss streak trigger | B11: 6
A13: How it works
A14: PAR: each panel runner's (time / ratio in) estimates what a 1.000-ratio runner would run today; par = MEDIAN of the three estimates, so one unrepresentative panel day is ignored.
A15: The panel are reliable runners who run the segment early, so everyone else knows their target (ratio x par) before running.
A16: Panel defaults to the names above; to use different runners for one segment, type their names over the panel cells (O2:O4) on that segment's sheet.
A17: If a panel runner has no time, their estimate is blank and the median uses the remaining two - name a substitute in O2:O4 instead where possible.
A18: SCORING: score = (target - time) / target, capped by the limits above; no time = no-run penalty; team score = average of team members' scores.
A19: RATIO UPDATE: new ratio = ratio - weight x (ratio - time/par). Weight is the calibration weight while a runner has calibration runs remaining (new joiners and returners), else the standard weight.
A20: NEW JOINER: add team + name + time on any blank row; their ratio self-seeds as time/par (debut score = 0 by construction) and they get the calibration weight for their next runs.
A21: RETURNER: a runner missing [miss streak trigger] consecutive segments keeps their ratio but is re-granted [calibration runs granted] calibration-weight runs when they return.
A22: NEXT SEGMENT: enter times on Next Segment as runners post them (blank = did not run). When closed: rename the sheet to the segment name; duplicate it; rename the copy Next Segment; clear its Time column; find&replace the previous sheet name in columns D/E/F; extend Ratio History.
A23: RESULTS: the shareable live view. It pulls from whatever sheet is named in its cell B1 (default Next Segment), so it updates as times are entered and automatically shows each new segment. To look back at a closed segment, type that sheet name into B1. Scores shade red to green (dark red = no-run penalty, grey = lower cap, dark green = upper cap); team and runner ranks 1/2/3 show gold/silver/bronze.

Sheet Roster
A1: Runner | B1: Team | C1: Start Ratio | D1: Calibration Runs Left | E1: Missed In A Row
A2: Ben Wernick | B2: 1 | C2: 1 | D2: 0 | E2: 0
A3: Tom Rhoden | B3: 1 | C3: 1.0709679 | D3: 0 | E3: 0
A4: Anne Marie Moon | B4: 1 | C4: 1.1695392 | D4: 0 | E4: 0
A5: Lisa King | B5: 1 | C5: 1.2849811 | D5: 0 | E5: 0
A6: Luke Sibieta | B6: 2 | C6: 1.0609519 | D6: 0 | E6: 0
A7: Mark Emery | B7: 2 | C7: 0.97 | D7: 0 | E7: 0
A8: Matt Snell | B8: 2 | C8: 1.14 | D8: 0 | E8: 0
A9: Gareth Lawrence | B9: 2 | C9: 1.2819962 | D9: 0 | E9: 0
A10: Neil Price | B10: 3 | C10: 1.1409077 | D10: 0 | E10: 0
A11: Rhidian Jones | B11: 3 | C11: 1.2158634 | D11: 0 | E11: 0
A12: Andy Shanahan | B12: 3 | C12: 1.3448276 | D12: 0 | E12: 0
A13: Rachel Price | B13: 4 | C13: 1.2401122 | D13: 0 | E13: 0
... A30: Beth Palmer | B30: 7 | C30: 1.4442628 | D30: 0 | E30: 0

Sheet Sting in the tail
A1: Team | B1: Runner | C1: Time | D1: Ratio In | E1: Calibration Runs Left (in) | F1: Missed In A Row (in) | G1: Target | H1: Score | I1: Day Ratio | J1: Weight | K1: New Ratio | L1: Calibration Runs Left (out) | M1: Missed In A Row (out) | O1: Panel par estimates (time / ratio in) | R1: Team | S1: Team Score | T1: Rank
A2: 1 | B2: Ben Wernick | C2: 0.0096296296 | D2: =IF($B2="","",IFERROR(VLOOKUP($B2,Roster!$A$2:$C$200,3,FALSE),IF($C2="","",$C2/$P$5))) -> 1 | E2: =IF($B2="","",IFERROR(VLOOKUP($B2,Roster!$A$2:$D$200,4,FALSE),Control!$B$10)) -> 0 | F2: =IF($B2="","",IFERROR(VLOOKUP($B2,Roster!$A$2:$E$200,5,FALSE),0)) -> 0 | G2: =IF($D2="","",$D2*$P$5) -> 0.0096389652 | H2: =IF($D2="","",IF($C2="",Control!$B$9,MAX(MIN(($G2-$C2)/$G2,Control!$B$7),Control!$B$8))) -> 0.00096852824 | I2: =IF($D2="","",IF($C2="",$D2,$C2/$P$5)) -> 0.99903147 | J2: =IF($D2="","",IF($E2>0,Control!$B$6,Control!$B$5)) -> 0.33333333 | K2: =IF($D2="","",$D2-$J2*($D2-$I2)) -> 0.99967716 | L2: =IF($B2="","",IF($C2="",IF($M2>=Control!$B$11,Control!$B$10,$E2),MAX($E2-1,0))) -> 0 | M2: =IF($B2="","",IF($C2="",$F2+1,0)) -> 0 | O2: =Control!$B$2 -> Ben Wernick | P2: =IFERROR(IF(VLOOKUP($O2,$B$2:$C$36,2,FALSE)=0,"",VLOOKUP($O2,$B$2:$C$36,2,FALSE)/VLOOKUP($O2,$B$2:$D$36,3,FALSE)),"") -> 0.0096296296 | R2: 1 | S2: =AVERAGEIF($A$2:$A$36,$R2,$H$2:$H$36) -> 0.0070708531 | T2: =RANK($S2,$S$2:$S$8) -> 1
A3: 1 | B3: Tom Rhoden | C3: 0.01025463 | D3: =IF($B3="","",IFERROR(VLOOKUP($B3,Roster!$A$2:$C$200,3,FALSE),IF($C3="","",$C3/$P$5))) -> 1.0709679 | E3: =IF($B3="","",IFERROR(VLOOKUP($B3,Roster!$A$2:$D$200,4,FALSE),Control!$B$10)) -> 0 | F3: =IF($B3="","",IFERROR(VLOOKUP($B3,Roster!$A$2:$E$200,5,FALSE),0)) -> 0 | G3: =IF($D3="","",$D3*$P$5) -> 0.010323023 | H3: =IF($D3="","",IF($C3="",Control!$B$9,MAX(MIN(($G3-$C3)/$G3,Control!$B$7),Control!$B$8))) -> 0.0066253075 | I3: =IF($D3="","",IF($C3="",$D3,$C3/$P$5)) -> 1.0638725 | J3: =IF($D3="","",IF($E3>0,Control!$B$6,Control!$B$5)) -> 0.33333333 | K3: =IF($D3="","",$D3-$J3*($D3-$I3)) -> 1.0686028 | L3: =IF($B3="","",IF($C3="",IF($M3>=Control!$B$11,Control!$B$10,$E3),MAX($E3-1,0))) -> 0 | M3: =IF($B3="","",IF($C3="",$F3+1,0)) -> 0 | O3: =Control!$B$3 -> Mark Emery | P3: =IFERROR(IF(VLOOKUP($O3,$B$2:$C$36,2,FALSE)=0,"",VLOOKUP($O3,$B$2:$C$36,2,FALSE)/VLOOKUP($O3,$B$2:$D$36,3,FALSE)),"") -> 0.010333142 | R3: 2 | S3: =AVERAGEIF($A$2:$A$36,$R3,$H$2:$H$36) -> 0.0039469496 | T3: =RANK($S3,$S$2:$S$8) -> 3
A4: 1 | B4: Anne Marie Moon | C4: 0.011273148 | D4: =IF($B4="","",IFERROR(VLOOKUP($B4,Roster!$A$2:$C$200,3,FALSE),IF($C4="","",$C4/$P$5))) -> 1.1695392 | E4: =IF($B4="","",IFERROR(VLOOKUP($B4,Roster!$A$2:$D$200,4,FALSE),Control!$B$10)) -> 0 | F4: =IF($B4="","",IFERROR(VLOOKUP($B4,Roster!$A$2:$E$200,5,FALSE),0)) -> 0 | G4: =IF($D4="","",$D4*$P$5) -> 0.011273148 | H4: =IF($D4="","",IF($C4="",Control!$B$9,MAX(MIN(($G4-$C4)/$G4,Control!$B$7),Control!$B$8))) -> 0 | I4: =IF($D4="","",IF($C4="",$D4,$C4/$P$5)) -> 1.1695392 | J4: =IF($D4="","",IF($E4>0,Control!$B$6,Control!$B$5)) -> 0.33333333 | K4: =IF($D4="","",$D4-$J4*($D4-$I4)) -> 1.1695392 | L4: =IF($B4="","",IF($C4="",IF($M4>=Control!$B$11,Control!$B$10,$E4),MAX($E4-1,0))) -> 0 | M4: =IF($B4="","",IF($C4="",$F4+1,0)) -> 0 | O4: =Control!$B$4 -> Anne Marie Moon | P4: =IFERROR(IF(VLOOKUP($O4,$B$2:$C$36,2,FALSE)=0,"",VLOOKUP($O4,$B$2:$C$36,2,FALSE)/VLOOKUP($O4,$B$2:$D$36,3,FALSE)),"") -> 0.0096389652 | R4: 3 | S4: =AVERAGEIF($A$2:$A$36,$R4,$H$2:$H$36) -> -0.0037225012 | T4: =RANK($S4,$S$2:$S$8) -> 6
A5: 1 | B5: Lisa King | C5: 0.01212963 | D5: =IF($B5="","",IFERROR(VLOOKUP($B5,Roster!$A$2:$C$200,3,FALSE),IF($C5="","",$C5/$P$5))) -> 1.2849811 | E5: =IF($B5="","",IFERROR(VLOOKUP($B5,Roster!$A$2:$D$200,4,FALSE),Control!$B$10)) -> 0 | F5: =IF($B5="","",IFERROR(VLOOKUP($B5,Roster!$A$2:$E$200,5,FALSE),0)) -> 0 | G5: =IF($D5="","",$D5*$P$5) -> 0.012385888 | H5: =IF($D5="","",IF($C5="",Control!$B$9,MAX(MIN(($G5-$C5)/$G5,Control!$B$7),Control!$B$8))) -> 0.020689577 | I5: =IF($D5="","",IF($C5="",$D5,$C5/$P$5)) -> 1.2583954 | J5: =IF($D5="","",IF($E5>0,Control!$B$6,Control!$B$5)) -> 0.33333333 | K5: =IF($D5="","",$D5-$J5*($D5-$I5)) -> 1.2761192 | L5: =IF($B5="","",IF($C5="",IF($M5>=Control!$B$11,Control!$B$10,$E5),MAX($E5-1,0))) -> 0 | M5: =IF($B5="","",IF($C5="",$F5+1,0)) -> 0 | O5: PAR (median of panel) | P5: =MEDIAN(P2:P4) -> 0.0096389652 | R5: 4 | S5: =AVERAGEIF($A$2:$A$36,$R5,$H$2:$H$36) -> 0.0040921769 | T5: =RANK($S5,$S$2:$S$8) -> 2
A6: 2 | B6: Luke Sibieta | C6: 0.0099652778 | D6: =IF($B6="","",IFERROR(VLOOKUP($B6,Roster!$A$2:$C$200,3,FALSE),IF($C6="","",$C6/$P$5))) -> 1.0609519 | E6: =IF($B6="","",IFERROR(VLOOKUP($B6,Roster!$A$2:$D$200,4,FALSE),Control!$B$10)) -> 0 | F6: =IF($B6="","",IFERROR(VLOOKUP($B6,Roster!$A$2:$E$200,5,FALSE),0)) -> 0 | G6: =IF($D6="","",$D6*$P$5) -> 0.010226479 | H6: =IF($D6="","",IF($C6="",Control!$B$9,MAX(MIN(($G6-$C6)/$G6,Control!$B$7),Control!$B$8))) -> 0.025541629 | I6: =IF($D6="","",IF($C6="",$D6,$C6/$P$5)) -> 1.0338535 | J6: =IF($D6="","",IF($E6>0,Control!$B$6,Control!$B$5)) -> 0.33333333 | K6: =IF($D6="","",$D6-$J6*($D6-$I6)) -> 1.0519191 | L6: =IF($B6="","",IF($C6="",IF($M6>=Control!$B$11,Control!$B$10,$E6),MAX($E6-1,0))) -> 0 | M6: =IF($B6="","",IF($C6="",$F6+1,0)) -> 0 | R6: 5 | S6: =AVERAGEIF($A$2:$A$36,$R6,$H$2:$H$36) -> -0.010386847 | T6: =RANK($S6,$S$2:$S$8) -> 7
A7: 2 | B7: Mark Emery | C7: 0.010023148 | D7: =IF($B7="","",IFERROR(VLOOKUP($B7,Roster!$A$2:$C$200,3,FALSE),IF($C7="","",$C7/$P$5))) -> 0.97 | E7: =IF($B7="","",IFERROR(VLOOKUP($B7,Roster!$A$2:$D$200,4,FALSE),Control!$B$10)) -> 0 | F7: =IF($B7="","",IFERROR(VLOOKUP($B7,Roster!$A$2:$E$200,5,FALSE),0)) -> 0 | G7: =IF($D7="","",$D7*$P$5) -> 0.0093497963 | H7: =IF($D7="","",IF($C7="",Control!$B$9,MAX(MIN(($G7-$C7)/$G7,Control!$B$7),Control!$B$8))) -> -0.05 | I7: =IF($D7="","",IF($C7="",$D7,$C7/$P$5)) -> 1.0398573 | J7: =IF($D7="","",IF($E7>0,Control!$B$6,Control!$B$5)) -> 0.33333333 | K7: =IF($D7="","",$D7-$J7*($D7-$I7)) -> 0.99328576 | L7: =IF($B7="","",IF($C7="",IF($M7>=Control!$B$11,Control!$B$10,$E7),MAX($E7-1,0))) -> 0 | M7: =IF($B7="","",IF($C7="",$F7+1,0)) -> 0 | R7: 6 | S7: =AVERAGEIF($A$2:$A$36,$R7,$H$2:$H$36) -> 0.0032736643 | T7: =RANK($S7,$S$2:$S$8) -> 4
A8: 2 | B8: Matt Snell | C8: 0.010717593 | D8: =IF($B8="","",IFERROR(VLOOKUP($B8,Roster!$A$2:$C$200,3,FALSE),IF($C8="","",$C8/$P$5))) -> 1.14 | E8: =IF($B8="","",IFERROR(VLOOKUP($B8,Roster!$A$2:$D$200,4,FALSE),Control!$B$10)) -> 0 | F8: =IF($B8="","",IFERROR(VLOOKUP($B8,Roster!$A$2:$E$200,5,FALSE),0)) -> 0 | G8: =IF($D8="","",$D8*$P$5) -> 0.01098842 | H8: =IF($D8="","",IF($C8="",Control!$B$9,MAX(MIN(($G8-$C8)/$G8,Control!$B$7),Control!$B$8))) -> 0.024646653 | I8: =IF($D8="","",IF($C8="",$D8,$C8/$P$5)) -> 1.1119028 | J8: =IF($D8="","",IF($E8>0,Control!$B$6,Control!$B$5)) -> 0.33333333 | K8: =IF($D8="","",$D8-$J8*($D8-$I8)) -> 1.1306343 | L8: =IF($B8="","",IF($C8="",IF($M8>=Control!$B$11,Control!$B$10,$E8),MAX($E8-1,0))) -> 0 | M8: =IF($B8="","",IF($C8="",$F8+1,0)) -> 0 | R8: 7 | S8: =AVERAGEIF($A$2:$A$36,$R8,$H$2:$H$36) -> 0.0023424113 | T8: =RANK($S8,$S$2:$S$8) -> 5
A9: 2 | B9: Gareth Lawrence | C9: 0.012164352 | D9: =IF($B9="","",IFERROR(VLOOKUP($B9,Roster!$A$2:$C$200,3,FALSE),IF($C9="","",$C9/$P$5))) -> 1.2819962 | E9: =IF($B9="","",IFERROR(VLOOKUP($B9,Roster!$A$2:$D$200,4,FALSE),Control!$B$10)) -> 0 | F9: =IF($B9="","",IFERROR(VLOOKUP($B9,Roster!$A$2:$E$200,5,FALSE),0)) -> 0 | G9: =IF($D9="","",$D9*$P$5) -> 0.012357117 | H9: =IF($D9="","",IF($C9="",Control!$B$9,MAX(MIN(($G9-$C9)/$G9,Control!$B$7),Control!$B$8))) -> 0.015599516 | I9: =IF($D9="","",IF($C9="",$D9,$C9/$P$5)) -> 1.2619977 | J9: =IF($D9="","",IF($E9>0,Control!$B$6,Control!$B$5)) -> 0.33333333 | K9: =IF($D9="","",$D9-$J9*($D9-$I9)) -> 1.27533 | L9: =IF($B9="","",IF($C9="",IF($M9>=Control!$B$11,Control!$B$10,$E9),MAX($E9-1,0))) -> 0 | M9: =IF($B9="","",IF($C9="",$F9+1,0)) -> 0
A10: 3 | B10: Neil Price | C10: 0.010486111 | D10: =IF($B10="","",IFERROR(VLOOKUP($B10,Roster!$A$2:$C$200,3,FALSE),IF($C10="","",$C10/$P$5))) -> 1.1409077 | E10: =IF($B10="","",IFERROR(VLOOKUP($B10,Roster!$A$2:$D$200,4,FALSE),Control!$B$10)) -> 0 | F10: =IF($B10="","",IFERROR(VLOOKUP($B10,Roster!$A$2:$E$200,5,FALSE),0)) -> 0 | G10: =IF($D10="","",$D10*$P$5) -> 0.01099717 | H10: =IF($D10="","",IF($C10="",Control!$B$9,MAX(MIN(($G10-$C10)/$G10,Control!$B$7),Control!$B$8))) -> 0.046471824 | I10: =IF($D10="","",IF($C10="",$D10,$C10/$P$5)) -> 1.0878876 | J10: =IF($D10="","",IF($E10>0,Control!$B$6,Control!$B$5)) -> 0.33333333 | K10: =IF($D10="","",$D10-$J10*($D10-$I10)) -> 1.1232343 | L10: =IF($B10="","",IF($C10="",IF($M10>=Control!$B$11,Control!$B$10,$E10),MAX($E10-1,0))) -> 0 | M10: =IF($B10="","",IF($C10="",$F10+1,0)) -> 0
A11: 3 | B11: Rhidian Jones | C11: 0.011516204 | D11: =IF($B11="","",IFERROR(VLOOKUP($B11,Roster!$A$2:$C$200,3,FALSE),IF($C11="","",$C11/$P$5))) -> 1.2158634 | E11: =IF($B11="","",IFERROR(VLOOKUP($B11,Roster!$A$2:$D$200,4,FALSE),Control!$B$10)) -> 0 | F11: =IF($B11="","",IFERROR(VLOOKUP($B11,Roster!$A$2:$E$200,5,FALSE),0)) -> 0 | G11: =IF($D11="","",$D11*$P$5) -> 0.011719665 | H11: =IF($D11="","",IF($C11="",Control!$B$9,MAX(MIN(($G11-$C11)/$G11,Control!$B$7),Control!$B$8))) -> 0.017360672 | I11: =IF($D11="","",IF($C11="",$D11,$C11/$P$5)) -> 1.1947552 | J11: =IF($D11="","",IF($E11>0,Control!$B$6,Control!$B$5)) -> 0.33333333 | K11: =IF($D11="","",$D11-$J11*($D11-$I11)) -> 1.2088273 | L11: =IF($B11="","",IF($C11="",IF($M11>=Control!$B$11,Control!$B$10,$E11),MAX($E11-1,0))) -> 0 | M11: =IF($B11="","",IF($C11="",$F11+1,0)) -> 0
A12: 3 | B12: Andy Shanahan | D12: =IF($B12="","",IFERROR(VLOOKUP($B12,Roster!$A$2:$C$200,3,FALSE),IF($C12="","",$C12/$P$5))) -> 1.3448276 | E12: =IF($B12="","",IFERROR(VLOOKUP($B12,Roster!$A$2:$D$200,4,FALSE),Control!$B$10)) -> 0 | F12: =IF($B12="","",IFERROR(VLOOKUP($B12,Roster!$A$2:$E$200,5,FALSE),0)) -> 0 | G12: =IF($D12="","",$D12*$P$5) -> 0.012962746 | H12: =IF($D12="","",IF($C12="",Control!$B$9,MAX(MIN(($G12-$C12)/$G12,Control!$B$7),Control!$B$8))) -> -0.075 | I12: =IF($D12="","",IF($C12="",$D12,$C12/$P$5)) -> 1.3448276 | J12: =IF($D12="","",IF($E12>0,Control!$B$6,Control!$B$5)) -> 0.33333333 | K12: =IF($D12="","",$D12-$J12*($D12-$I12)) -> 1.3448276 | L12: =IF($B12="","",IF($C12="",IF($M12>=Control!$B$11,Control!$B$10,$E12),MAX($E12-1,0))) -> 0 | M12: =IF($B12="","",IF($C12="",$F12+1,0)) -> 1
A13: 4 | B13: Rachel Price | C13: 0.011655093 | D13: =IF($B13="","",IFERROR(VLOOKUP($B13,Roster!$A$2:$C$200,3,FALSE),IF($C13="","",$C13/$P$5))) -> 1.2401122 | E13: =IF($B13="","",IFERROR(VLOOKUP($B13,Roster!$A$2:$D$200,4,FALSE),Control!$B$10)) -> 0 | F13: =IF($B13="","",IFERROR(VLOOKUP($B13,Roster!$A$2:$E$200,5,FALSE),0)) -> 0 | G13: =IF($D13="","",$D13*$P$5) -> 0.011953398 | H13: =IF($D13="","",IF($C13="",Control!$B$9,MAX(MIN(($G13-$C13)/$G13,Control!$B$7),Control!$B$8))) -> 0.024955715 | I13: =IF($D13="","",IF($C13="",$D13,$C13/$P$5)) -> 1.2091643 | J13: =IF($D13="","",IF($E13>0,Control!$B$6,Control!$B$5)) -> 0.33333333 | K13: =IF($D13="","",$D13-$J13*($D13-$I13)) -> 1.2297962 | L13: =IF($B13="","",IF($C13="",IF($M13>=Control!$B$11,Control!$B$10,$E13),MAX($E13-1,0))) -> 0 | M13: =IF($B13="","",IF($C13="",$F13+1,0)) -> 0
A14: 4 | B14: Emma Jones | C14: 0.015578704 | D14: =IF($B14="","",IFERROR(VLOOKUP($B14,Roster!$A$2:$C$200,3,FALSE),IF($C14="","",$C14/$P$5))) -> 1.6105308 | E14: =IF($B14="","",IFERROR(VLOOKUP($B14,Roster!$A$2:$D$200,4,FALSE),Control!$B$10)) -> 0 | F14: =IF($B14="","",IFERROR(VLOOKUP($B14,Roster!$A$2:$E$200,5,FALSE),0)) -> 0 | G14: =IF($D14="","",$D14*$P$5) -> 0.01552385 | H14: =IF($D14="","",IF($C14="",Control!$B$9,MAX(MIN(($G14-$C14)/$G14,Control!$B$7),Control!$B$8))) -> -0.0035335138 | I14: =IF($D14="","",IF($C14="",$D14,$C14/$P$5)) -> 1.6162216 | J14: =IF($D14="","",IF($E14>0,Control!$B$6,Control!$B$5)) -> 0.33333333 | K14: =IF($D14="","",$D14-$J14*($D14-$I14)) -> 1.6124277 | L14: =IF($B14="","",IF($C14="",IF($M14>=Control!$B$11,Control!$B$10,$E14),MAX($E14-1,0))) -> 0 | M14: =IF($B14="","",IF($C14="",$F14+1,0)) -> 0
A15: 4 | B15: Claire Emery | C15: 0.015625 | D15: =IF($B15="","",IFERROR(VLOOKUP($B15,Roster!$A$2:$C$200,3,FALSE),IF($C15="","",$C15/$P$5))) -> 1.6175321 | E15: =IF($B15="","",IFERROR(VLOOKUP($B15,Roster!$A$2:$D$200,4,FALSE),Control!$B$10)) -> 0 | F15: =IF($B15="","",IFERROR(VLOOKUP($B15,Roster!$A$2:$E$200,5,FALSE),0)) -> 0 | G15: =IF($D15="","",$D15*$P$5) -> 0.015591335 | H15: =IF($D15="","",IF($C15="",Control!$B$9,MAX(MIN(($G15-$C15)/$G15,Control!$B$7),Control!$B$8))) -> -0.0021591982 | I15: =IF($D15="","",IF($C15="",$D15,$C15/$P$5)) -> 1.6210246 | J15: =IF($D15="","",IF($E15>0,Control!$B$6,Control!$B$5)) -> 0.33333333 | K15: =IF($D15="","",$D15-$J15*($D15-$I15)) -> 1.6186962 | L15: =IF($B15="","",IF($C15="",IF($M15>=Control!$B$11,Control!$B$10,$E15),MAX($E15-1,0))) -> 0 | M15: =IF($B15="","",IF($C15="",$F15+1,0)) -> 0
A16: 4 | B16: Helen Lawrence | C16: 0.015960648 | D16: =IF($B16="","",IFERROR(VLOOKUP($B16,Roster!$A$2:$C$200,3,FALSE),IF($C16="","",$C16/$P$5))) -> 1.651068 | E16: =IF($B16="","",IFERROR(VLOOKUP($B16,Roster!$A$2:$D$200,4,FALSE),Control!$B$10)) -> 0 | F16: =IF($B16="","",IFERROR(VLOOKUP($B16,Roster!$A$2:$E$200,5,FALSE),0)) -> 0 | G16: =IF($D16="","",$D16*$P$5) -> 0.015914587 | H16: =IF($D16="","",IF($C16="",Control!$B$9,MAX(MIN(($G16-$C16)/$G16,Control!$B$7),Control!$B$8))) -> -0.0028942953 | I16: =IF($D16="","",IF($C16="",$D16,$C16/$P$5)) -> 1.6558466 | J16: =IF($D16="","",IF($E16>0,Control!$B$6,Control!$B$5)) -> 0.33333333 | K16: =IF($D16="","",$D16-$J16*($D16-$I16)) -> 1.6526608 | L16: =IF($B16="","",IF($C16="",IF($M16>=Control!$B$11,Control!$B$10,$E16),MAX($E16-1,0))) -> 0 | M16: =IF($B16="","",IF($C16="",$F16+1,0)) -> 0
A17: 5 | B17: Ebony Vanderras | C17: 0.010625 | D17: =IF($B17="","",IFERROR(VLOOKUP($B17,Roster!$A$2:$C$200,3,FALSE),IF($C17="","",$C17/$P$5))) -> 1.1144551 | E17: =IF($B17="","",IFERROR(VLOOKUP($B17,Roster!$A$2:$D$200,4,FALSE),Control!$B$10)) -> 0 | F17: =IF($B17="","",IFERROR(VLOOKUP($B17,Roster!$A$2:$E$200,5,FALSE),0)) -> 0 | G17: =IF($D17="","",$D17*$P$5) -> 0.010742194 | H17: =IF($D17="","",IF($C17="",Control!$B$9,MAX(MIN(($G17-$C17)/$G17,Control!$B$7),Control!$B$8))) -> 0.010909712 | I17: =IF($D17="","",IF($C17="",$D17,$C17/$P$5)) -> 1.1022967 | J17: =IF($D17="","",IF($E17>0,Control!$B$6,Control!$B$5)) -> 0.33333333 | K17: =IF($D17="","",$D17-$J17*($D17-$I17)) -> 1.1104023 | L17: =IF($B17="","",IF($C17="",IF($M17>=Control!$B$11,Control!$B$10,$E17),MAX($E17-1,0))) -> 0 | M17: =IF($B17="","",IF($C17="",$F17+1,0)) -> 0
A18: 5 | B18: Jennifer Morris | C18: 0.013275463 | D18: =IF($B18="","",IFERROR(VLOOKUP($B18,Roster!$A$2:$C$200,3,FALSE),IF($C18="","",$C18/$P$5))) -> 1.3723936 | E18: =IF($B18="","",IFERROR(VLOOKUP($B18,Roster!$A$2:$D$200,4,FALSE),Control!$B$10)) -> 0 | F18: =IF($B18="","",IFERROR(VLOOKUP($B18,Roster!$A$2:$E$200,5,FALSE),0)) -> 0 | G18: =IF($D18="","",$D18*$P$5) -> 0.013228454 | H18: =IF($D18="","",IF($C18="",Control!$B$9,MAX(MIN(($G18-$C18)/$G18,Control!$B$7),Control!$B$8))) -> -0.0035536278 | I18: =IF($D18="","",IF($C18="",$D18,$C18/$P$5)) -> 1.3772706 | J18: =IF($D18="","",IF($E18>0,Control!$B$6,Control!$B$5)) -> 0.33333333 | K18: =IF($D18="","",$D18-$J18*($D18-$I18)) -> 1.3740192 | L18: =IF($B18="","",IF($C18="",IF($M18>=Control!$B$11,Control!$B$10,$E18),MAX($E18-1,0))) -> 0 | M18: =IF($B18="","",IF($C18="",$F18+1,0)) -> 0
A19: 5 | B19: Keziah Rhoden | C19: 0.013969907 | D19: =IF($B19="","",IFERROR(VLOOKUP($B19,Roster!$A$2:$C$200,3,FALSE),IF($C19="","",$C19/$P$5))) -> 1.4509071 | E19: =IF($B19="","",IFERROR(VLOOKUP($B19,Roster!$A$2:$D$200,4,FALSE),Control!$B$10)) -> 0 | F19: =IF($B19="","",IFERROR(VLOOKUP($B19,Roster!$A$2:$E$200,5,FALSE),0)) -> 0 | G19: =IF($D19="","",$D19*$P$5) -> 0.013985243 | H19: =IF($D19="","",IF($C19="",Control!$B$9,MAX(MIN(($G19-$C19)/$G19,Control!$B$7),Control!$B$8))) -> 0.0010965291 | I19: =IF($D19="","",IF($C19="",$D19,$C19/$P$5)) -> 1.4493161 | J19: =IF($D19="","",IF($E19>0,Control!$B$6,Control!$B$5)) -> 0.33333333 | K19: =IF($D19="","",$D19-$J19*($D19-$I19)) -> 1.4503767 | L19: =IF($B19="","",IF($C19="",IF($M19>=Control!$B$11,Control!$B$10,$E19),MAX($E19-1,0))) -> 0 | M19: =IF($B19="","",IF($C19="",$F19+1,0)) -> 0
A20: 5 | B20: Lizz Ryan | C20: 0.01806713 | D20: =IF($B20="","",IFERROR(VLOOKUP($B20,Roster!$A$2:$C$200,3,FALSE),IF($C20="","",$C20/$P$5))) -> 1.568734 | E20: =IF($B20="","",IFERROR(VLOOKUP($B20,Roster!$A$2:$D$200,4,FALSE),Control!$B$10)) -> 0 | F20: =IF($B20="","",IFERROR(VLOOKUP($B20,Roster!$A$2:$E$200,5,FALSE),0)) -> 0 | G20: =IF($D20="","",$D20*$P$5) -> 0.015120972 | H20: =IF($D20="","",IF($C20="",Control!$B$9,MAX(MIN(($G20-$C20)/$G20,Control!$B$7),Control!$B$8))) -> -0.05 | I20: =IF($D20="","",IF($C20="",$D20,$C20/$P$5)) -> 1.8743848 | J20: =IF($D20="","",IF($E20>0,Control!$B$6,Control!$B$5)) -> 0.33333333 | K20: =IF($D20="","",$D20-$J20*($D20-$I20)) -> 1.6706176 | L20: =IF($B20="","",IF($C20="",IF($M20>=Control!$B$11,Control!$B$10,$E20),MAX($E20-1,0))) -> 0 | M20: =IF($B20="","",IF($C20="",$F20+1,0)) -> 0
A21: 6 | B21: Sarah Woods | C21: 0.013136574 | D21: =IF($B21="","",IFERROR(VLOOKUP($B21,Roster!$A$2:$C$200,3,FALSE),IF($C21="","",$C21/$P$5))) -> 1.3888581 | E21: =IF($B21="","",IFERROR(VLOOKUP($B21,Roster!$A$2:$D$200,4,FALSE),Control!$B$10)) -> 0 | F21: =IF($B21="","",IFERROR(VLOOKUP($B21,Roster!$A$2:$E$200,5,FALSE),0)) -> 0 | G21: =IF($D21="","",$D21*$P$5) -> 0.013387155 | H21: =IF($D21="","",IF($C21="",Control!$B$9,MAX(MIN(($G21-$C21)/$G21,Control!$B$7),Control!$B$8))) -> 0.018718033 | I21: =IF($D21="","",IF($C21="",$D21,$C21/$P$5)) -> 1.3628614 | J21: =IF($D21="","",IF($E21>0,Control!$B$6,Control!$B$5)) -> 0.33333333 | K21: =IF($D21="","",$D21-$J21*($D21-$I21)) -> 1.3801926 | L21: =IF($B21="","",IF($C21="",IF($M21>=Control!$B$11,Control!$B$10,$E21),MAX($E21-1,0))) -> 0 | M21: =IF($B21="","",IF($C21="",$F21+1,0)) -> 0
A22: 6 | B22: Sarah Felvus | C22: 0.0134375 | D22: =IF($B22="","",IFERROR(VLOOKUP($B22,Roster!$A$2:$C$200,3,FALSE),IF($C22="","",$C22/$P$5))) -> 1.3814596 | E22: =IF($B22="","",IFERROR(VLOOKUP($B22,Roster!$A$2:$D$200,4,FALSE),Control!$B$10)) -> 0 | F22: =IF($B22="","",IFERROR(VLOOKUP($B22,Roster!$A$2:$E$200,5,FALSE),0)) -> 0 | G22: =IF($D22="","",$D22*$P$5) -> 0.013315842 | H22: =IF($D22="","",IF($C22="",Control!$B$9,MAX(MIN(($G22-$C22)/$G22,Control!$B$7),Control!$B$8))) -> -0.0091363699 | I22: =IF($D22="","",IF($C22="",$D22,$C22/$P$5)) -> 1.3940812 | J22: =IF($D22="","",IF($E22>0,Control!$B$6,Control!$B$5)) -> 0.33333333 | K22: =IF($D22="","",$D22-$J22*($D22-$I22)) -> 1.3856668 | L22: =IF($B22="","",IF($C22="",IF($M22>=Control!$B$11,Control!$B$10,$E22),MAX($E22-1,0))) -> 0 | M22: =IF($B22="","",IF($C22="",$F22+1,0)) -> 0
A23: 6 | B23: Nia Williams | C23: 0.015023148 | D23: =IF($B23="","",IFERROR(VLOOKUP($B23,Roster!$A$2:$C$200,3,FALSE),IF($C23="","",$C23/$P$5))) -> 1.5858349 | E23: =IF($B23="","",IFERROR(VLOOKUP($B23,Roster!$A$2:$D$200,4,FALSE),Control!$B$10)) -> 0 | F23: =IF($B23="","",IFERROR(VLOOKUP($B23,Roster!$A$2:$E$200,5,FALSE),0)) -> 0 | G23: =IF($D23="","",$D23*$P$5) -> 0.015285808 | H23: =IF($D23="","",IF($C23="",Control!$B$9,MAX(MIN(($G23-$C23)/$G23,Control!$B$7),Control!$B$8))) -> 0.017183227 | I23: =IF($D23="","",IF($C23="",$D23,$C23/$P$5)) -> 1.5585852 | J23: =IF($D23="","",IF($E23>0,Control!$B$6,Control!$B$5)) -> 0.33333333 | K23: =IF($D23="","",$D23-$J23*($D23-$I23)) -> 1.5767517 | L23: =IF($B23="","",IF($C23="",IF($M23>=Control!$B$11,Control!$B$10,$E23),MAX($E23-1,0))) -> 0 | M23: =IF($B23="","",IF($C23="",$F23+1,0)) -> 0
A24: 6 | B24: Janine Payne | C24: 0.016712963 | D24: =IF($B24="","",IFERROR(VLOOKUP($B24,Roster!$A$2:$C$200,3,FALSE),IF($C24="","",$C24/$P$5))) -> 1.7185256 | E24: =IF($B24="","",IFERROR(VLOOKUP($B24,Roster!$A$2:$D$200,4,FALSE),Control!$B$10)) -> 0 | F24: =IF($B24="","",IFERROR(VLOOKUP($B24,Roster!$A$2:$E$200,5,FALSE),0)) -> 0 | G24: =IF($D24="","",$D24*$P$5) -> 0.016564809 | H24: =IF($D24="","",IF($C24="",Control!$B$9,MAX(MIN(($G24-$C24)/$G24,Control!$B$7),Control!$B$8))) -> -0.0089439031 | I24: =IF($D24="","",IF($C24="",$D24,$C24/$P$5)) -> 1.733896 | J24: =IF($D24="","",IF($E24>0,Control!$B$6,Control!$B$5)) -> 0.33333333 | K24: =IF($D24="","",$D24-$J24*($D24-$I24)) -> 1.7236491 | L24: =IF($B24="","",IF($C24="",IF($M24>=Control!$B$11,Control!$B$10,$E24),MAX($E24-1,0))) -> 0 | M24: =IF($B24="","",IF($C24="",$F24+1,0)) -> 0
... A30: 7 | B30: Beth Palmer | C30: 0.014375 | D30: =IF($B30="","",IFERROR(VLOOKUP($B30,Roster!$A$2:$C$200,3,FALSE),IF($C30="","",$C30/$P$5))) -> 1.4442628 | E30: =IF($B30="","",IFERROR(VLOOKUP($B30,Roster!$A$2:$D$200,4,FALSE),Control!$B$10)) -> 0 | F30: =IF($B30="","",IFERROR(VLOOKUP($B30,Roster!$A$2:$E$200,5,FALSE),0)) -> 0 | G30: =IF($D30="","",$D30*$P$5) -> 0.013921199 | H30: =IF($D30="","",IF($C30="",Control!$B$9,MAX(MIN(($G30-$C30)/$G30,Control!$B$7),Control!$B$8))) -> -0.03259783 | I30: =IF($D30="","",IF($C30="",$D30,$C30/$P$5)) -> 1.4913427 | J30: =IF($D30="","",IF($E30>0,Control!$B$6,Control!$B$5)) -> 0.33333333 | K30: =IF($D30="","",$D30-$J30*($D30-$I30)) -> 1.4599561 | L30: =IF($B30="","",IF($C30="",IF($M30>=Control!$B$11,Control!$B$10,$E30),MAX($E30-1,0))) -> 0 | M30: =IF($B30="","",IF($C30="",$F30+1,0)) -> 0
D31: =IF($B31="","",IFERROR(VLOOKUP($B31,Roster!$A$2:$C$200,3,FALSE),IF($C31="","",$C31/$P$5))) | E31: =IF($B31="","",IFERROR(VLOOKUP($B31,Roster!$A$2:$D$200,4,FALSE),Control!$B$10)) | F31: =IF($B31="","",IFERROR(VLOOKUP($B31,Roster!$A$2:$E$200,5,FALSE),0)) | G31: =IF($D31="","",$D31*$P$5) | H31: =IF($D31="","",IF($C31="",Control!$B$9,MAX(MIN(($G31-$C31)/$G31,Control!$B$7),Control!$B$8))) | I31: =IF($D31="","",IF($C31="",$D31,$C31/$P$5)) | J31: =IF($D31="","",IF($E31>0,Control!$B$6,Control!$B$5)) | K31: =IF($D31="","",$D31-$J31*($D31-$I31)) | L31: =IF($B31="","",IF($C31="",IF($M31>=Control!$B$11,Control!$B$10,$E31),MAX($E31-1,0))) | M31: =IF($B31="","",IF($C31="",$F31+1,0))
D32: =IF($B32="","",IFERROR(VLOOKUP($B32,Roster!$A$2:$C$200,3,FALSE),IF($C32="","",$C32/$P$5))) | E32: =IF($B32="","",IFERROR(VLOOKUP($B32,Roster!$A$2:$D$200,4,FALSE),Control!$B$10)) | F32: =IF($B32="","",IFERROR(VLOOKUP($B32,Roster!$A$2:$E$200,5,FALSE),0)) | G32: =IF($D32="","",$D32*$P$5) | H32: =IF($D32="","",IF($C32="",Control!$B$9,MAX(MIN(($G32-$C32)/$G32,Control!$B$7),Control!$B$8))) | I32: =IF($D32="","",IF($C32="",$D32,$C32/$P$5)) | J32: =IF($D32="","",IF($E32>0,Control!$B$6,Control!$B$5)) | K32: =IF($D32="","",$D32-$J32*($D32-$I32)) | L32: =IF($B32="","",IF($C32="",IF($M32>=Control!$B$11,Control!$B$10,$E32),MAX($E32-1,0))) | M32: =IF($B32="","",IF($C32="",$F32+1,0))
D33: =IF($B33="","",IFERROR(VLOOKUP($B33,Roster!$A$2:$C$200,3,FALSE),IF($C33="","",$C33/$P$5))) | E33: =IF($B33="","",IFERROR(VLOOKUP($B33,Roster!$A$2:$D$200,4,FALSE),Control!$B$10)) | F33: =IF($B33="","",IFERROR(VLOOKUP($B33,Roster!$A$2:$E$200,5,FALSE),0)) | G33: =IF($D33="","",$D33*$P$5) | H33: =IF($D33="","",IF($C33="",Control!$B$9,MAX(MIN(($G33-$C33)/$G33,Control!$B$7),Control!$B$8))) | I33: =IF($D33="","",IF($C33="",$D33,$C33/$P$5)) | J33: =IF($D33="","",IF($E33>0,Control!$B$6,Control!$B$5)) | K33: =IF($D33="","",$D33-$J33*($D33-$I33)) | L33: =IF($B33="","",IF($C33="",IF($M33>=Control!$B$11,Control!$B$10,$E33),MAX($E33-1,0))) | M33: =IF($B33="","",IF($C33="",$F33+1,0))
D34: =IF($B34="","",IFERROR(VLOOKUP($B34,Roster!$A$2:$C$200,3,FALSE),IF($C34="","",$C34/$P$5))) | E34: =IF($B34="","",IFERROR(VLOOKUP($B34,Roster!$A$2:$D$200,4,FALSE),Control!$B$10)) | F34: =IF($B34="","",IFERROR(VLOOKUP($B34,Roster!$A$2:$E$200,5,FALSE),0)) | G34: =IF($D34="","",$D34*$P$5) | H34: =IF($D34="","",IF($C34="",Control!$B$9,MAX(MIN(($G34-$C34)/$G34,Control!$B$7),Control!$B$8))) | I34: =IF($D34="","",IF($C34="",$D34,$C34/$P$5)) | J34: =IF($D34="","",IF($E34>0,Control!$B$6,Control!$B$5)) | K34: =IF($D34="","",$D34-$J34*($D34-$I34)) | L34: =IF($B34="","",IF($C34="",IF($M34>=Control!$B$11,Control!$B$10,$E34),MAX($E34-1,0))) | M34: =IF($B34="","",IF($C34="",$F34+1,0))
D35: =IF($B35="","",IFERROR(VLOOKUP($B35,Roster!$A$2:$C$200,3,FALSE),IF($C35="","",$C35/$P$5))) | E35: =IF($B35="","",IFERROR(VLOOKUP($B35,Roster!$A$2:$D$200,4,FALSE),Control!$B$10)) | F35: =IF($B35="","",IFERROR(VLOOKUP($B35,Roster!$A$2:$E$200,5,FALSE),0)) | G35: =IF($D35="","",$D35*$P$5) | H35: =IF($D35="","",IF($C35="",Control!$B$9,MAX(MIN(($G35-$C35)/$G35,Control!$B$7),Control!$B$8))) | I35: =IF($D35="","",IF($C35="",$D35,$C35/$P$5)) | J35: =IF($D35="","",IF($E35>0,Control!$B$6,Control!$B$5)) | K35: =IF($D35="","",$D35-$J35*($D35-$I35)) | L35: =IF($B35="","",IF($C35="",IF($M35>=Control!$B$11,Control!$B$10,$E35),MAX($E35-1,0))) | M35: =IF($B35="","",IF($C35="",$F35+1,0))
D36: =IF($B36="","",IFERROR(VLOOKUP($B36,Roster!$A$2:$C$200,3,FALSE),IF($C36="","",$C36/$P$5))) | E36: =IF($B36="","",IFERROR(VLOOKUP($B36,Roster!$A$2:$D$200,4,FALSE),Control!$B$10)) | F36: =IF($B36="","",IFERROR(VLOOKUP($B36,Roster!$A$2:$E$200,5,FALSE),0)) | G36: =IF($D36="","",$D36*$P$5) | H36: =IF($D36="","",IF($C36="",Control!$B$9,MAX(MIN(($G36-$C36)/$G36,Control!$B$7),Control!$B$8))) | I36: =IF($D36="","",IF($C36="",$D36,$C36/$P$5)) | J36: =IF($D36="","",IF($E36>0,Control!$B$6,Control!$B$5)) | K36: =IF($D36="","",$D36-$J36*($D36-$I36)) | L36: =IF($B36="","",IF($C36="",IF($M36>=Control!$B$11,Control!$B$10,$E36),MAX($E36-1,0))) | M36: =IF($B36="","",IF($C36="",$F36+1,0))

Sheet Dune Bugger
A1: Team | B1: Runner | C1: Time | D1: Ratio In | E1: Calibration Runs Left (in) | F1: Missed In A Row (in) | G1: Target | H1: Score | I1: Day Ratio | J1: Weight | K1: New Ratio | L1: Calibration Runs Left (out) | M1: Missed In A Row (out) | O1: Panel par estimates (time / ratio in) | R1: Team | S1: Team Score | T1: Rank
A2: 1 | B2: Ben Wernick | C2: 0.0078819444 | D2: =IF($B2="","",IFERROR(VLOOKUP($B2,'Sting in the tail'!$B$2:$M$36,10,FALSE),IF($C2="","",$C2/$P$5))) -> 0.99967716 | E2: =IF($B2="","",IFERROR(VLOOKUP($B2,'Sting in the tail'!$B$2:$M$36,11,FALSE),Control!$B$10)) -> 0 | F2: =IF($B2="","",IFERROR(VLOOKUP($B2,'Sting in the tail'!$B$2:$M$36,12,FALSE),0)) -> 0 | G2: =IF($D2="","",$D2*$P$5) -> 0.007825421 | H2: =IF($D2="","",IF($C2="",Control!$B$9,MAX(MIN(($G2-$C2)/$G2,Control!$B$7),Control!$B$8))) -> -0.0072230599 | I2: =IF($D2="","",IF($C2="",$D2,$C2/$P$5)) -> 1.0068979 | J2: =IF($D2="","",IF($E2>0,Control!$B$6,Control!$B$5)) -> 0.33333333 | K2: =IF($D2="","",$D2-$J2*($D2-$I2)) -> 1.0020841 | L2: =IF($B2="","",IF($C2="",IF($M2>=Control!$B$11,Control!$B$10,$E2),MAX($E2-1,0))) -> 0 | M2: =IF($B2="","",IF($C2="",$F2+1,0)) -> 0 | O2: =Control!$B$2 -> Ben Wernick | P2: =IFERROR(IF(VLOOKUP($O2,$B$2:$C$36,2,FALSE)=0,"",VLOOKUP($O2,$B$2:$C$36,2,FALSE)/VLOOKUP($O2,$B$2:$D$36,3,FALSE)),"") -> 0.0078844899 | R2: 1 | S2: =AVERAGEIF($A$2:$A$36,$R2,$H$2:$H$36) -> -0.014624606 | T2: =RANK($S2,$S$2:$S$8) -> 5
A3: 1 | B3: Tom Rhoden | C3: 0.0087268519 | D3: =IF($B3="","",IFERROR(VLOOKUP($B3,'Sting in the tail'!$B$2:$M$36,10,FALSE),IF($C3="","",$C3/$P$5))) -> 1.0686028 | E3: =IF($B3="","",IFERROR(VLOOKUP($B3,'Sting in the tail'!$B$2:$M$36,11,FALSE),Control!$B$10)) -> 0 | F3: =IF($B3="","",IFERROR(VLOOKUP($B3,'Sting in the tail'!$B$2:$M$36,12,FALSE),0)) -> 0 | G3: =IF($D3="","",$D3*$P$5) -> 0.0083649672 | H3: =IF($D3="","",IF($C3="",Control!$B$9,MAX(MIN(($G3-$C3)/$G3,Control!$B$7),Control!$B$8))) -> -0.043261933 | I3: =IF($D3="","",IF($C3="",$D3,$C3/$P$5)) -> 1.1148326 | J3: =IF($D3="","",IF($E3>0,Control!$B$6,Control!$B$5)) -> 0.33333333 | K3: =IF($D3="","",$D3-$J3*($D3-$I3)) -> 1.0840127 | L3: =IF($B3="","",IF($C3="",IF($M3>=Control!$B$11,Control!$B$10,$E3),MAX($E3-1,0))) -> 0 | M3: =IF($B3="","",IF($C3="",$F3+1,0)) -> 0 | O3: =Control!$B$3 -> Mark Emery | P3: =IFERROR(IF(VLOOKUP($O3,$B$2:$C$36,2,FALSE)=0,"",VLOOKUP($O3,$B$2:$C$36,2,FALSE)/VLOOKUP($O3,$B$2:$D$36,3,FALSE)),"") -> 0.0073526079 | R3: 2 | S3: =AVERAGEIF($A$2:$A$36,$R3,$H$2:$H$36) -> 0.010353933 | T3: =RANK($S3,$S$2:$S$8) -> 2
A4: 1 | B4: Anne Marie Moon | C4: 0.0091550926 | D4: =IF($B4="","",IFERROR(VLOOKUP($B4,'Sting in the tail'!$B$2:$M$36,10,FALSE),IF($C4="","",$C4/$P$5))) -> 1.1695392 | E4: =IF($B4="","",IFERROR(VLOOKUP($B4,'Sting in the tail'!$B$2:$M$36,11,FALSE),Control!$B$10)) -> 0 | F4: =IF($B4="","",IFERROR(VLOOKUP($B4,'Sting in the tail'!$B$2:$M$36,12,FALSE),0)) -> 0 | G4: =IF($D4="","",$D4*$P$5) -> 0.0091550926 | H4: =IF($D4="","",IF($C4="",Control!$B$9,MAX(MIN(($G4-$C4)/$G4,Control!$B$7),Control!$B$8))) -> 0 | I4: =IF($D4="","",IF($C4="",$D4,$C4/$P$5)) -> 1.1695392 | J4: =IF($D4="","",IF($E4>0,Control!$B$6,Control!$B$5)) -> 0.33333333 | K4: =IF($D4="","",$D4-$J4*($D4-$I4)) -> 1.1695392 | L4: =IF($B4="","",IF($C4="",IF($M4>=Control!$B$11,Control!$B$10,$E4),MAX($E4-1,0))) -> 0 | M4: =IF($B4="","",IF($C4="",$F4+1,0)) -> 0 | O4: =Control!$B$4 -> Anne Marie Moon | P4: =IFERROR(IF(VLOOKUP($O4,$B$2:$C$36,2,FALSE)=0,"",VLOOKUP($O4,$B$2:$C$36,2,FALSE)/VLOOKUP($O4,$B$2:$D$36,3,FALSE)),"") -> 0.0078279482 | R4: 3 | S4: =AVERAGEIF($A$2:$A$36,$R4,$H$2:$H$36) -> -0.029281985 | T4: =RANK($S4,$S$2:$S$8) -> 7
A5: 1 | B5: Lisa King | C5: 0.010069444 | D5: =IF($B5="","",IFERROR(VLOOKUP($B5,'Sting in the tail'!$B$2:$M$36,10,FALSE),IF($C5="","",$C5/$P$5))) -> 1.2761192 | E5: =IF($B5="","",IFERROR(VLOOKUP($B5,'Sting in the tail'!$B$2:$M$36,11,FALSE),Control!$B$10)) -> 0 | F5: =IF($B5="","",IFERROR(VLOOKUP($B5,'Sting in the tail'!$B$2:$M$36,12,FALSE),0)) -> 0 | G5: =IF($D5="","",$D5*$P$5) -> 0.0099893951 | H5: =IF($D5="","",IF($C5="",Control!$B$9,MAX(MIN(($G5-$C5)/$G5,Control!$B$7),Control!$B$8))) -> -0.0080134315 | I5: =IF($D5="","",IF($C5="",$D5,$C5/$P$5)) -> 1.2863453 | J5: =IF($D5="","",IF($E5>0,Control!$B$6,Control!$B$5)) -> 0.33333333 | K5: =IF($D5="","",$D5-$J5*($D5-$I5)) -> 1.2795279 | L5: =IF($B5="","",IF($C5="",IF($M5>=Control!$B$11,Control!$B$10,$E5),MAX($E5-1,0))) -> 0 | M5: =IF($B5="","",IF($C5="",$F5+1,0)) -> 0 | O5: PAR (median of panel) | P5: =MEDIAN(P2:P4) -> 0.0078279482 | R5: 4 | S5: =AVERAGEIF($A$2:$A$36,$R5,$H$2:$H$36) -> 0.016484049 | T5: =RANK($S5,$S$2:$S$8) -> 1
A6: 2 | B6: Mark Emery | C6: 0.0073032407 | D6: =IF($B6="","",IFERROR(VLOOKUP($B6,'Sting in the tail'!$B$2:$M$36,10,FALSE),IF($C6="","",$C6/$P$5))) -> 0.99328576 | E6: =IF($B6="","",IFERROR(VLOOKUP($B6,'Sting in the tail'!$B$2:$M$36,11,FALSE),Control!$B$10)) -> 0 | F6: =IF($B6="","",IFERROR(VLOOKUP($B6,'Sting in the tail'!$B$2:$M$36,12,FALSE),0)) -> 0 | G6: =IF($D6="","",$D6*$P$5) -> 0.0077753894 | H6: =IF($D6="","",IF($C6="",Control!$B$9,MAX(MIN(($G6-$C6)/$G6,Control!$B$7),Control!$B$8))) -> 0.05 | I6: =IF($D6="","",IF($C6="",$D6,$C6/$P$5)) -> 0.93296999 | J6: =IF($D6="","",IF($E6>0,Control!$B$6,Control!$B$5)) -> 0.33333333 | K6: =IF($D6="","",$D6-$J6*($D6-$I6)) -> 0.9731805 | L6: =IF($B6="","",IF($C6="",IF($M6>=Control!$B$11,Control!$B$10,$E6),MAX($E6-1,0))) -> 0 | M6: =IF($B6="","",IF($C6="",$F6+1,0)) -> 0 | R6: 5 | S6: =AVERAGEIF($A$2:$A$36,$R6,$H$2:$H$36) -> -0.021528639 | T6: =RANK($S6,$S$2:$S$8) -> 6
A7: 2 | B7: Luke Sibieta | C7: 0.0081712963 | D7: =IF($B7="","",IFERROR(VLOOKUP($B7,'Sting in the tail'!$B$2:$M$36,10,FALSE),IF($C7="","",$C7/$P$5))) -> 1.0519191 | E7: =IF($B7="","",IFERROR(VLOOKUP($B7,'Sting in the tail'!$B$2:$M$36,11,FALSE),Control!$B$10)) -> 0 | F7: =IF($B7="","",IFERROR(VLOOKUP($B7,'Sting in the tail'!$B$2:$M$36,12,FALSE),0)) -> 0 | G7: =IF($D7="","",$D7*$P$5) -> 0.0082343683 | H7: =IF($D7="","",IF($C7="",Control!$B$9,MAX(MIN(($G7-$C7)/$G7,Control!$B$7),Control!$B$8))) -> 0.0076595988 | I7: =IF($D7="","",IF($C7="",$D7,$C7/$P$5)) -> 1.0438618 | J7: =IF($D7="","",IF($E7>0,Control!$B$6,Control!$B$5)) -> 0.33333333 | K7: =IF($D7="","",$D7-$J7*($D7-$I7)) -> 1.0492333 | L7: =IF($B7="","",IF($C7="",IF($M7>=Control!$B$11,Control!$B$10,$E7),MAX($E7-1,0))) -> 0 | M7: =IF($B7="","",IF($C7="",$F7+1,0)) -> 0 | R7: 6 | S7: =AVERAGEIF($A$2:$A$36,$R7,$H$2:$H$36) -> -0.0013250832 | T7: =RANK($S7,$S$2:$S$8) -> 3
A8: 2 | B8: Matt Snell | C8: 0.0086921296 | D8: =IF($B8="","",IFERROR(VLOOKUP($B8,'Sting in the tail'!$B$2:$M$36,10,FALSE),IF($C8="","",$C8/$P$5))) -> 1.1306343 | E8: =IF($B8="","",IFERROR(VLOOKUP($B8,'Sting in the tail'!$B$2:$M$36,11,FALSE),Control!$B$10)) -> 0 | F8: =IF($B8="","",IFERROR(VLOOKUP($B8,'Sting in the tail'!$B$2:$M$36,12,FALSE),0)) -> 0 | G8: =IF($D8="","",$D8*$P$5) -> 0.0088505465 | H8: =IF($D8="","",IF($C8="",Control!$B$9,MAX(MIN(($G8-$C8)/$G8,Control!$B$7),Control!$B$8))) -> 0.017899102 | I8: =IF($D8="","",IF($C8="",$D8,$C8/$P$5)) -> 1.1103969 | J8: =IF($D8="","",IF($E8>0,Control!$B$6,Control!$B$5)) -> 0.33333333 | K8: =IF($D8="","",$D8-$J8*($D8-$I8)) -> 1.1238885 | L8: =IF($B8="","",IF($C8="",IF($M8>=Control!$B$11,Control!$B$10,$E8),MAX($E8-1,0))) -> 0 | M8: =IF($B8="","",IF($C8="",$F8+1,0)) -> 0 | R8: 7 | S8: =AVERAGEIF($A$2:$A$36,$R8,$H$2:$H$36) -> -0.014527594 | T8: =RANK($S8,$S$2:$S$8) -> 4
A9: 2 | B9: Gareth Lawrence | C9: 0.010324074 | D9: =IF($B9="","",IFERROR(VLOOKUP($B9,'Sting in the tail'!$B$2:$M$36,10,FALSE),IF($C9="","",$C9/$P$5))) -> 1.27533 | E9: =IF($B9="","",IFERROR(VLOOKUP($B9,'Sting in the tail'!$B$2:$M$36,11,FALSE),Control!$B$10)) -> 0 | F9: =IF($B9="","",IFERROR(VLOOKUP($B9,'Sting in the tail'!$B$2:$M$36,12,FALSE),0)) -> 0 | G9: =IF($D9="","",$D9*$P$5) -> 0.0099832174 | H9: =IF($D9="","",IF($C9="",Control!$B$9,MAX(MIN(($G9-$C9)/$G9,Control!$B$7),Control!$B$8))) -> -0.034142968 | I9: =IF($D9="","",IF($C9="",$D9,$C9/$P$5)) -> 1.3188736 | J9: =IF($D9="","",IF($E9>0,Control!$B$6,Control!$B$5)) -> 0.33333333 | K9: =IF($D9="","",$D9-$J9*($D9-$I9)) -> 1.2898446 | L9: =IF($B9="","",IF($C9="",IF($M9>=Control!$B$11,Control!$B$10,$E9),MAX($E9-1,0))) -> 0 | M9: =IF($B9="","",IF($C9="",$F9+1,0)) -> 0
A10: 3 | B10: Rhidian Jones | C10: 0.0099305556 | D10: =IF($B10="","",IFERROR(VLOOKUP($B10,'Sting in the tail'!$B$2:$M$36,10,FALSE),IF($C10="","",$C10/$P$5))) -> 1.2088273 | E10: =IF($B10="","",IFERROR(VLOOKUP($B10,'Sting in the tail'!$B$2:$M$36,11,FALSE),Control!$B$10)) -> 0 | F10: =IF($B10="","",IFERROR(VLOOKUP($B10,'Sting in the tail'!$B$2:$M$36,12,FALSE),0)) -> 0 | G10: =IF($D10="","",$D10*$P$5) -> 0.0094626376 | H10: =IF($D10="","",IF($C10="",Control!$B$9,MAX(MIN(($G10-$C10)/$G10,Control!$B$7),Control!$B$8))) -> -0.049448997 | I10: =IF($D10="","",IF($C10="",$D10,$C10/$P$5)) -> 1.2686026 | J10: =IF($D10="","",IF($E10>0,Control!$B$6,Control!$B$5)) -> 0.33333333 | K10: =IF($D10="","",$D10-$J10*($D10-$I10)) -> 1.2287524 | L10: =IF($B10="","",IF($C10="",IF($M10>=Control!$B$11,Control!$B$10,$E10),MAX($E10-1,0))) -> 0 | M10: =IF($B10="","",IF($C10="",$F10+1,0)) -> 0
A11: 3 | B11: Neil Price | C11: 0.010115741 | D11: =IF($B11="","",IFERROR(VLOOKUP($B11,'Sting in the tail'!$B$2:$M$36,10,FALSE),IF($C11="","",$C11/$P$5))) -> 1.1232343 | E11: =IF($B11="","",IFERROR(VLOOKUP($B11,'Sting in the tail'!$B$2:$M$36,11,FALSE),Control!$B$10)) -> 0 | F11: =IF($B11="","",IFERROR(VLOOKUP($B11,'Sting in the tail'!$B$2:$M$36,12,FALSE),0)) -> 0 | G11: =IF($D11="","",$D11*$P$5) -> 0.0087926202 | H11: =IF($D11="","",IF($C11="",Control!$B$9,MAX(MIN(($G11-$C11)/$G11,Control!$B$7),Control!$B$8))) -> -0.05 | I11: =IF($D11="","",IF($C11="",$D11,$C11/$P$5)) -> 1.2922595 | J11: =IF($D11="","",IF($E11>0,Control!$B$6,Control!$B$5)) -> 0.33333333 | K11: =IF($D11="","",$D11-$J11*($D11-$I11)) -> 1.1795761 | L11: =IF($B11="","",IF($C11="",IF($M11>=Control!$B$11,Control!$B$10,$E11),MAX($E11-1,0))) -> 0 | M11: =IF($B11="","",IF($C11="",$F11+1,0)) -> 0
A12: 3 | B12: Andy Shanahan | C12: 0.010405093 | D12: =IF($B12="","",IFERROR(VLOOKUP($B12,'Sting in the tail'!$B$2:$M$36,10,FALSE),IF($C12="","",$C12/$P$5))) -> 1.3448276 | E12: =IF($B12="","",IFERROR(VLOOKUP($B12,'Sting in the tail'!$B$2:$M$36,11,FALSE),Control!$B$10)) -> 0 | F12: =IF($B12="","",IFERROR(VLOOKUP($B12,'Sting in the tail'!$B$2:$M$36,12,FALSE),0)) -> 1 | G12: =IF($D12="","",$D12*$P$5) -> 0.010527241 | H12: =IF($D12="","",IF($C12="",Control!$B$9,MAX(MIN(($G12-$C12)/$G12,Control!$B$7),Control!$B$8))) -> 0.011603044 | I12: =IF($D12="","",IF($C12="",$D12,$C12/$P$5)) -> 1.3292235 | J12: =IF($D12="","",IF($E12>0,Control!$B$6,Control!$B$5)) -> 0.33333333 | K12: =IF($D12="","",$D12-$J12*($D12-$I12)) -> 1.3396262 | L12: =IF($B12="","",IF($C12="",IF($M12>=Control!$B$11,Control!$B$10,$E12),MAX($E12-1,0))) -> 0 | M12: =IF($B12="","",IF($C12="",$F12+1,0)) -> 0
A13: 4 | B13: Rachel Price | C13: 0.01005787 | D13: =IF($B13="","",IFERROR(VLOOKUP($B13,'Sting in the tail'!$B$2:$M$36,10,FALSE),IF($C13="","",$C13/$P$5))) -> 1.2297962 | E13: =IF($B13="","",IFERROR(VLOOKUP($B13,'Sting in the tail'!$B$2:$M$36,11,FALSE),Control!$B$10)) -> 0 | F13: =IF($B13="","",IFERROR(VLOOKUP($B13,'Sting in the tail'!$B$2:$M$36,12,FALSE),0)) -> 0 | G13: =IF($D13="","",$D13*$P$5) -> 0.009626781 | H13: =IF($D13="","",IF($C13="",Control!$B$9,MAX(MIN(($G13-$C13)/$G13,Control!$B$7),Control!$B$8))) -> -0.044780216 | I13: =IF($D13="","",IF($C13="",$D13,$C13/$P$5)) -> 1.2848668 | J13: =IF($D13="","",IF($E13>0,Control!$B$6,Control!$B$5)) -> 0.33333333 | K13: =IF($D13="","",$D13-$J13*($D13-$I13)) -> 1.2481531 | L13: =IF($B13="","",IF($C13="",IF($M13>=Control!$B$11,Control!$B$10,$E13),MAX($E13-1,0))) -> 0 | M13: =IF($B13="","",IF($C13="",$F13+1,0)) -> 0
A14: 4 | B14: Emma Jones | C14: 0.012175926 | D14: =IF($B14="","",IFERROR(VLOOKUP($B14,'Sting in the tail'!$B$2:$M$36,10,FALSE),IF($C14="","",$C14/$P$5))) -> 1.6124277 | E14: =IF($B14="","",IFERROR(VLOOKUP($B14,'Sting in the tail'!$B$2:$M$36,11,FALSE),Control!$B$10)) -> 0 | F14: =IF($B14="","",IFERROR(VLOOKUP($B14,'Sting in the tail'!$B$2:$M$36,12,FALSE),0)) -> 0 | G14: =IF($D14="","",$D14*$P$5) -> 0.012622 | H14: =IF($D14="","",IF($C14="",Control!$B$9,MAX(MIN(($G14-$C14)/$G14,Control!$B$7),Control!$B$8))) -> 0.035341031 | I14: =IF($D14="","",IF($C14="",$D14,$C14/$P$5)) -> 1.5554428 | J14: =IF($D14="","",IF($E14>0,Control!$B$6,Control!$B$5)) -> 0.33333333 | K14: =IF($D14="","",$D14-$J14*($D14-$I14)) -> 1.5934327 | L14: =IF($B14="","",IF($C14="",IF($M14>=Control!$B$11,Control!$B$10,$E14),MAX($E14-1,0))) -> 0 | M14: =IF($B14="","",IF($C14="",$F14+1,0)) -> 0
A15: 4 | B15: Helen Lawrence | C15: 0.012175926 | D15: =IF($B15="","",IFERROR(VLOOKUP($B15,'Sting in the tail'!$B$2:$M$36,10,FALSE),IF($C15="","",$C15/$P$5))) -> 1.6526608 | E15: =IF($B15="","",IFERROR(VLOOKUP($B15,'Sting in the tail'!$B$2:$M$36,11,FALSE),Control!$B$10)) -> 0 | F15: =IF($B15="","",IFERROR(VLOOKUP($B15,'Sting in the tail'!$B$2:$M$36,12,FALSE),0)) -> 0 | G15: =IF($D15="","",$D15*$P$5) -> 0.012936943 | H15: =IF($D15="","",IF($C15="",Control!$B$9,MAX(MIN(($G15-$C15)/$G15,Control!$B$7),Control!$B$8))) -> 0.05 | I15: =IF($D15="","",IF($C15="",$D15,$C15/$P$5)) -> 1.5554428 | J15: =IF($D15="","",IF($E15>0,Control!$B$6,Control!$B$5)) -> 0.33333333 | K15: =IF($D15="","",$D15-$J15*($D15-$I15)) -> 1.6202548 | L15: =IF($B15="","",IF($C15="",IF($M15>=Control!$B$11,Control!$B$10,$E15),MAX($E15-1,0))) -> 0 | M15: =IF($B15="","",IF($C15="",$F15+1,0)) -> 0
A16: 4 | B16: Claire Emery | C16: 0.012349537 | D16: =IF($B16="","",IFERROR(VLOOKUP($B16,'Sting in the tail'!$B$2:$M$36,10,FALSE),IF($C16="","",$C16/$P$5))) -> 1.6186962 | E16: =IF($B16="","",IFERROR(VLOOKUP($B16,'Sting in the tail'!$B$2:$M$36,11,FALSE),Control!$B$10)) -> 0 | F16: =IF($B16="","",IFERROR(VLOOKUP($B16,'Sting in the tail'!$B$2:$M$36,12,FALSE),0)) -> 0 | G16: =IF($D16="","",$D16*$P$5) -> 0.01267107 | H16: =IF($D16="","",IF($C16="",Control!$B$9,MAX(MIN(($G16-$C16)/$G16,Control!$B$7),Control!$B$8))) -> 0.02537538 | I16: =IF($D16="","",IF($C16="",$D16,$C16/$P$5)) -> 1.5776212 | J16: =IF($D16="","",IF($E16>0,Control!$B$6,Control!$B$5)) -> 0.33333333 | K16: =IF($D16="","",$D16-$J16*($D16-$I16)) -> 1.6050046 | L16: =IF($B16="","",IF($C16="",IF($M16>=Control!$B$11,Control!$B$10,$E16),MAX($E16-1,0))) -> 0 | M16: =IF($B16="","",IF($C16="",$F16+1,0)) -> 0
A17: 5 | B17: Ebony Vanderras | C17: 0.0084027778 | D17: =IF($B17="","",IFERROR(VLOOKUP($B17,'Sting in the tail'!$B$2:$M$36,10,FALSE),IF($C17="","",$C17/$P$5))) -> 1.1104023 | E17: =IF($B17="","",IFERROR(VLOOKUP($B17,'Sting in the tail'!$B$2:$M$36,11,FALSE),Control!$B$10)) -> 0 | F17: =IF($B17="","",IFERROR(VLOOKUP($B17,'Sting in the tail'!$B$2:$M$36,12,FALSE),0)) -> 0 | G17: =IF($D17="","",$D17*$P$5) -> 0.0086921719 | H17: =IF($D17="","",IF($C17="",Control!$B$9,MAX(MIN(($G17-$C17)/$G17,Control!$B$7),Control!$B$8))) -> 0.033293649 | I17: =IF($D17="","",IF($C17="",$D17,$C17/$P$5)) -> 1.073433 | J17: =IF($D17="","",IF($E17>0,Control!$B$6,Control!$B$5)) -> 0.33333333 | K17: =IF($D17="","",$D17-$J17*($D17-$I17)) -> 1.0980792 | L17: =IF($B17="","",IF($C17="",IF($M17>=Control!$B$11,Control!$B$10,$E17),MAX($E17-1,0))) -> 0 | M17: =IF($B17="","",IF($C17="",$F17+1,0)) -> 0
A18: 5 | B18: Jennifer Morris | C18: 0.011666667 | D18: =IF($B18="","",IFERROR(VLOOKUP($B18,'Sting in the tail'!$B$2:$M$36,10,FALSE),IF($C18="","",$C18/$P$5))) -> 1.3740192 | E18: =IF($B18="","",IFERROR(VLOOKUP($B18,'Sting in the tail'!$B$2:$M$36,11,FALSE),Control!$B$10)) -> 0 | F18: =IF($B18="","",IFERROR(VLOOKUP($B18,'Sting in the tail'!$B$2:$M$36,12,FALSE),0)) -> 0 | G18: =IF($D18="","",$D18*$P$5) -> 0.010755751 | H18: =IF($D18="","",IF($C18="",Control!$B$9,MAX(MIN(($G18-$C18)/$G18,Control!$B$7),Control!$B$8))) -> -0.05 | I18: =IF($D18="","",IF($C18="",$D18,$C18/$P$5)) -> 1.4903863 | J18: =IF($D18="","",IF($E18>0,Control!$B$6,Control!$B$5)) -> 0.33333333 | K18: =IF($D18="","",$D18-$J18*($D18-$I18)) -> 1.4128083 | L18: =IF($B18="","",IF($C18="",IF($M18>=Control!$B$11,Control!$B$10,$E18),MAX($E18-1,0))) -> 0 | M18: =IF($B18="","",IF($C18="",$F18+1,0)) -> 0
A19: 5 | B19: Keziah Rhoden | C19: 0.011678241 | D19: =IF($B19="","",IFERROR(VLOOKUP($B19,'Sting in the tail'!$B$2:$M$36,10,FALSE),IF($C19="","",$C19/$P$5))) -> 1.4503767 | E19: =IF($B19="","",IFERROR(VLOOKUP($B19,'Sting in the tail'!$B$2:$M$36,11,FALSE),Control!$B$10)) -> 0 | F19: =IF($B19="","",IFERROR(VLOOKUP($B19,'Sting in the tail'!$B$2:$M$36,12,FALSE),0)) -> 0 | G19: =IF($D19="","",$D19*$P$5) -> 0.011353474 | H19: =IF($D19="","",IF($C19="",Control!$B$9,MAX(MIN(($G19-$C19)/$G19,Control!$B$7),Control!$B$8))) -> -0.028605067 | I19: =IF($D19="","",IF($C19="",$D19,$C19/$P$5)) -> 1.4918649 | J19: =IF($D19="","",IF($E19>0,Control!$B$6,Control!$B$5)) -> 0.33333333 | K19: =IF($D19="","",$D19-$J19*($D19-$I19)) -> 1.4642061 | L19: =IF($B19="","",IF($C19="",IF($M19>=Control!$B$11,Control!$B$10,$E19),MAX($E19-1,0))) -> 0 | M19: =IF($B19="","",IF($C19="",$F19+1,0)) -> 0
A20: 5 | B20: Lizz Ryan | C20: 0.013611111 | D20: =IF($B20="","",IFERROR(VLOOKUP($B20,'Sting in the tail'!$B$2:$M$36,10,FALSE),IF($C20="","",$C20/$P$5))) -> 1.6706176 | E20: =IF($B20="","",IFERROR(VLOOKUP($B20,'Sting in the tail'!$B$2:$M$36,11,FALSE),Control!$B$10)) -> 0 | F20: =IF($B20="","",IFERROR(VLOOKUP($B20,'Sting in the tail'!$B$2:$M$36,12,FALSE),0)) -> 0 | G20: =IF($D20="","",$D20*$P$5) -> 0.013077508 | H20: =IF($D20="","",IF($C20="",Control!$B$9,MAX(MIN(($G20-$C20)/$G20,Control!$B$7),Control!$B$8))) -> -0.040803139 | I20: =IF($D20="","",IF($C20="",$D20,$C20/$P$5)) -> 1.738784 | J20: =IF($D20="","",IF($E20>0,Control!$B$6,Control!$B$5)) -> 0.33333333 | K20: =IF($D20="","",$D20-$J20*($D20-$I20)) -> 1.6933397 | L20: =IF($B20="","",IF($C20="",IF($M20>=Control!$B$11,Control!$B$10,$E20),MAX($E20-1,0))) -> 0 | M20: =IF($B20="","",IF($C20="",$F20+1,0)) -> 0
... A30: 7 | B30: Beth Palmer | C30: 0.01224537 | D30: =IF($B30="","",IFERROR(VLOOKUP($B30,'Sting in the tail'!$B$2:$M$36,10,FALSE),IF($C30="","",$C30/$P$5))) -> 1.4599561 | E30: =IF($B30="","",IFERROR(VLOOKUP($B30,'Sting in the tail'!$B$2:$M$36,11,FALSE),Control!$B$10)) -> 0 | F30: =IF($B30="","",IFERROR(VLOOKUP($B30,'Sting in the tail'!$B$2:$M$36,12,FALSE),0)) -> 0 | G30: =IF($D30="","",$D30*$P$5) -> 0.011428461 | H30: =IF($D30="","",IF($C30="",Control!$B$9,MAX(MIN(($G30-$C30)/$G30,Control!$B$7),Control!$B$8))) -> -0.05 | I30: =IF($D30="","",IF($C30="",$D30,$C30/$P$5)) -> 1.5643142 | J30: =IF($D30="","",IF($E30>0,Control!$B$6,Control!$B$5)) -> 0.33333333 | K30: =IF($D30="","",$D30-$J30*($D30-$I30)) -> 1.4947421 | L30: =IF($B30="","",IF($C30="",IF($M30>=Control!$B$11,Control!$B$10,$E30),MAX($E30-1,0))) -> 0 | M30: =IF($B30="","",IF($C30="",$F30+1,0)) -> 0
D31: =IF($B31="","",IFERROR(VLOOKUP($B31,'Sting in the tail'!$B$2:$M$36,10,FALSE),IF($C31="","",$C31/$P$5))) | E31: =IF($B31="","",IFERROR(VLOOKUP($B31,'Sting in the tail'!$B$2:$M$36,11,FALSE),Control!$B$10)) | F31: =IF($B31="","",IFERROR(VLOOKUP($B31,'Sting in the tail'!$B$2:$M$36,12,FALSE),0)) | G31: =IF($D31="","",$D31*$P$5) | H31: =IF($D31="","",IF($C31="",Control!$B$9,MAX(MIN(($G31-$C31)/$G31,Control!$B$7),Control!$B$8))) | I31: =IF($D31="","",IF($C31="",$D31,$C31/$P$5)) | J31: =IF($D31="","",IF($E31>0,Control!$B$6,Control!$B$5)) | K31: =IF($D31="","",$D31-$J31*($D31-$I31)) | L31: =IF($B31="","",IF($C31="",IF($M31>=Control!$B$11,Control!$B$10,$E31),MAX($E31-1,0))) | M31: =IF($B31="","",IF($C31="",$F31+1,0))
D32: =IF($B32="","",IFERROR(VLOOKUP($B32,'Sting in the tail'!$B$2:$M$36,10,FALSE),IF($C32="","",$C32/$P$5))) | E32: =IF($B32="","",IFERROR(VLOOKUP($B32,'Sting in the tail'!$B$2:$M$36,11,FALSE),Control!$B$10)) | F32: =IF($B32="","",IFERROR(VLOOKUP($B32,'Sting in the tail'!$B$2:$M$36,12,FALSE),0)) | G32: =IF($D32="","",$D32*$P$5) | H32: =IF($D32="","",IF($C32="",Control!$B$9,MAX(MIN(($G32-$C32)/$G32,Control!$B$7),Control!$B$8))) | I32: =IF($D32="","",IF($C32="",$D32,$C32/$P$5)) | J32: =IF($D32="","",IF($E32>0,Control!$B$6,Control!$B$5)) | K32: =IF($D32="","",$D32-$J32*($D32-$I32)) | L32: =IF($B32="","",IF($C32="",IF($M32>=Control!$B$11,Control!$B$10,$E32),MAX($E32-1,0))) | M32: =IF($B32="","",IF($C32="",$F32+1,0))
D33: =IF($B33="","",IFERROR(VLOOKUP($B33,'Sting in the tail'!$B$2:$M$36,10,FALSE),IF($C33="","",$C33/$P$5))) | E33: =IF($B33="","",IFERROR(VLOOKUP($B33,'Sting in the tail'!$B$2:$M$36,11,FALSE),Control!$B$10)) | F33: =IF($B33="","",IFERROR(VLOOKUP($B33,'Sting in the tail'!$B$2:$M$36,12,FALSE),0)) | G33: =IF($D33="","",$D33*$P$5) | H33: =IF($D33="","",IF($C33="",Control!$B$9,MAX(MIN(($G33-$C33)/$G33,Control!$B$7),Control!$B$8))) | I33: =IF($D33="","",IF($C33="",$D33,$C33/$P$5)) | J33: =IF($D33="","",IF($E33>0,Control!$B$6,Control!$B$5)) | K33: =IF($D33="","",$D33-$J33*($D33-$I33)) | L33: =IF($B33="","",IF($C33="",IF($M33>=Control!$B$11,Control!$B$10,$E33),MAX($E33-1,0))) | M33: =IF($B33="","",IF($C33="",$F33+1,0))
